[2023-08-28 20:09:06,150] {taskinstance.py:1159} INFO - Dependencies all met for <TaskInstance: dados_climaticos.extrai_dados scheduled__2023-07-31T00:00:00+00:00 [queued]>
[2023-08-28 20:09:06,191] {taskinstance.py:1159} INFO - Dependencies all met for <TaskInstance: dados_climaticos.extrai_dados scheduled__2023-07-31T00:00:00+00:00 [queued]>
[2023-08-28 20:09:06,191] {taskinstance.py:1356} INFO - 
--------------------------------------------------------------------------------
[2023-08-28 20:09:06,192] {taskinstance.py:1357} INFO - Starting attempt 1 of 1
[2023-08-28 20:09:06,192] {taskinstance.py:1358} INFO - 
--------------------------------------------------------------------------------
[2023-08-28 20:09:06,239] {taskinstance.py:1377} INFO - Executing <Task(PythonOperator): extrai_dados> on 2023-07-31 00:00:00+00:00
[2023-08-28 20:09:06,299] {standard_task_runner.py:52} INFO - Started process 25166 to run task
[2023-08-28 20:09:06,320] {standard_task_runner.py:79} INFO - Running: ['airflow', 'tasks', 'run', 'dados_climaticos', 'extrai_dados', 'scheduled__2023-07-31T00:00:00+00:00', '--job-id', '14', '--raw', '--subdir', 'DAGS_FOLDER/dados_climaticos.py', '--cfg-path', '/tmp/tmpzyfahmud', '--error-file', '/tmp/tmpcs_et5d2']
[2023-08-28 20:09:06,325] {standard_task_runner.py:80} INFO - Job 14: Subtask extrai_dados
[2023-08-28 20:09:06,510] {task_command.py:370} INFO - Running <TaskInstance: dados_climaticos.extrai_dados scheduled__2023-07-31T00:00:00+00:00 [running]> on host FelipeBreve-PC.localdomain
[2023-08-28 20:09:06,604] {taskinstance.py:1889} ERROR - Task failed with exception
Traceback (most recent call last):
  File "/home/felipe/airflow/venv/lib/python3.9/site-packages/airflow/models/taskinstance.py", line 1451, in _run_raw_task
    self._execute_task_with_callbacks(context, test_mode)
  File "/home/felipe/airflow/venv/lib/python3.9/site-packages/airflow/models/taskinstance.py", line 1555, in _execute_task_with_callbacks
    task_orig = self.render_templates(context=context)
  File "/home/felipe/airflow/venv/lib/python3.9/site-packages/airflow/models/taskinstance.py", line 2212, in render_templates
    rendered_task = self.task.render_template_fields(context)
  File "/home/felipe/airflow/venv/lib/python3.9/site-packages/airflow/models/baseoperator.py", line 1185, in render_template_fields
    self._do_render_template_fields(self, self.template_fields, context, jinja_env, set())
  File "/home/felipe/airflow/venv/lib/python3.9/site-packages/airflow/utils/session.py", line 71, in wrapper
    return func(*args, session=session, **kwargs)
  File "/home/felipe/airflow/venv/lib/python3.9/site-packages/airflow/models/abstractoperator.py", line 344, in _do_render_template_fields
    rendered_content = self.render_template(
  File "/home/felipe/airflow/venv/lib/python3.9/site-packages/airflow/models/abstractoperator.py", line 404, in render_template
    return {key: self.render_template(value, context, jinja_env) for key, value in value.items()}
  File "/home/felipe/airflow/venv/lib/python3.9/site-packages/airflow/models/abstractoperator.py", line 404, in <dictcomp>
    return {key: self.render_template(value, context, jinja_env) for key, value in value.items()}
  File "/home/felipe/airflow/venv/lib/python3.9/site-packages/airflow/models/abstractoperator.py", line 387, in render_template
    template = jinja_env.from_string(value)
  File "/home/felipe/airflow/venv/lib/python3.9/site-packages/jinja2/environment.py", line 1092, in from_string
    return cls.from_code(self, self.compile(source), gs, None)
  File "/home/felipe/airflow/venv/lib/python3.9/site-packages/jinja2/environment.py", line 757, in compile
    self.handle_exception(source=source_hint)
  File "/home/felipe/airflow/venv/lib/python3.9/site-packages/jinja2/environment.py", line 925, in handle_exception
    raise rewrite_traceback_stack(source=source)
  File "<unknown>", line 1, in template
jinja2.exceptions.TemplateSyntaxError: unexpected char '"' at 29
[2023-08-28 20:09:06,626] {taskinstance.py:1395} INFO - Marking task as FAILED. dag_id=dados_climaticos, task_id=extrai_dados, execution_date=20230731T000000, start_date=20230828T230906, end_date=20230828T230906
[2023-08-28 20:09:06,666] {standard_task_runner.py:92} ERROR - Failed to execute job 14 for task extrai_dados (unexpected char '"' at 29; 25166)
[2023-08-28 20:09:06,700] {local_task_job.py:156} INFO - Task exited with return code 1
[2023-08-28 20:09:06,772] {local_task_job.py:273} INFO - 0 downstream tasks scheduled from follow-on schedule check
[2023-08-28 20:18:16,305] {taskinstance.py:1159} INFO - Dependencies all met for <TaskInstance: dados_climaticos.extrai_dados scheduled__2023-07-31T00:00:00+00:00 [queued]>
[2023-08-28 20:18:16,322] {taskinstance.py:1159} INFO - Dependencies all met for <TaskInstance: dados_climaticos.extrai_dados scheduled__2023-07-31T00:00:00+00:00 [queued]>
[2023-08-28 20:18:16,323] {taskinstance.py:1356} INFO - 
--------------------------------------------------------------------------------
[2023-08-28 20:18:16,323] {taskinstance.py:1357} INFO - Starting attempt 1 of 1
[2023-08-28 20:18:16,323] {taskinstance.py:1358} INFO - 
--------------------------------------------------------------------------------
[2023-08-28 20:18:16,356] {taskinstance.py:1377} INFO - Executing <Task(PythonOperator): extrai_dados> on 2023-07-31 00:00:00+00:00
[2023-08-28 20:18:16,410] {standard_task_runner.py:52} INFO - Started process 28853 to run task
[2023-08-28 20:18:16,430] {standard_task_runner.py:79} INFO - Running: ['airflow', 'tasks', 'run', 'dados_climaticos', 'extrai_dados', 'scheduled__2023-07-31T00:00:00+00:00', '--job-id', '26', '--raw', '--subdir', 'DAGS_FOLDER/dados_climaticos.py', '--cfg-path', '/tmp/tmp9mzj3tfv', '--error-file', '/tmp/tmp2714mtn2']
[2023-08-28 20:18:16,438] {standard_task_runner.py:80} INFO - Job 26: Subtask extrai_dados
[2023-08-28 20:18:16,592] {task_command.py:370} INFO - Running <TaskInstance: dados_climaticos.extrai_dados scheduled__2023-07-31T00:00:00+00:00 [running]> on host FelipeBreve-PC.localdomain
[2023-08-28 20:18:16,685] {taskinstance.py:1889} ERROR - Task failed with exception
Traceback (most recent call last):
  File "/home/felipe/airflow/venv/lib/python3.9/site-packages/airflow/models/taskinstance.py", line 1451, in _run_raw_task
    self._execute_task_with_callbacks(context, test_mode)
  File "/home/felipe/airflow/venv/lib/python3.9/site-packages/airflow/models/taskinstance.py", line 1555, in _execute_task_with_callbacks
    task_orig = self.render_templates(context=context)
  File "/home/felipe/airflow/venv/lib/python3.9/site-packages/airflow/models/taskinstance.py", line 2212, in render_templates
    rendered_task = self.task.render_template_fields(context)
  File "/home/felipe/airflow/venv/lib/python3.9/site-packages/airflow/models/baseoperator.py", line 1185, in render_template_fields
    self._do_render_template_fields(self, self.template_fields, context, jinja_env, set())
  File "/home/felipe/airflow/venv/lib/python3.9/site-packages/airflow/utils/session.py", line 71, in wrapper
    return func(*args, session=session, **kwargs)
  File "/home/felipe/airflow/venv/lib/python3.9/site-packages/airflow/models/abstractoperator.py", line 344, in _do_render_template_fields
    rendered_content = self.render_template(
  File "/home/felipe/airflow/venv/lib/python3.9/site-packages/airflow/models/abstractoperator.py", line 404, in render_template
    return {key: self.render_template(value, context, jinja_env) for key, value in value.items()}
  File "/home/felipe/airflow/venv/lib/python3.9/site-packages/airflow/models/abstractoperator.py", line 404, in <dictcomp>
    return {key: self.render_template(value, context, jinja_env) for key, value in value.items()}
  File "/home/felipe/airflow/venv/lib/python3.9/site-packages/airflow/models/abstractoperator.py", line 387, in render_template
    template = jinja_env.from_string(value)
  File "/home/felipe/airflow/venv/lib/python3.9/site-packages/jinja2/environment.py", line 1092, in from_string
    return cls.from_code(self, self.compile(source), gs, None)
  File "/home/felipe/airflow/venv/lib/python3.9/site-packages/jinja2/environment.py", line 757, in compile
    self.handle_exception(source=source_hint)
  File "/home/felipe/airflow/venv/lib/python3.9/site-packages/jinja2/environment.py", line 925, in handle_exception
    raise rewrite_traceback_stack(source=source)
  File "<unknown>", line 1, in template
jinja2.exceptions.TemplateSyntaxError: unexpected char '"' at 29
[2023-08-28 20:18:16,777] {taskinstance.py:1395} INFO - Marking task as FAILED. dag_id=dados_climaticos, task_id=extrai_dados, execution_date=20230731T000000, start_date=20230828T231816, end_date=20230828T231816
[2023-08-28 20:18:16,808] {standard_task_runner.py:92} ERROR - Failed to execute job 26 for task extrai_dados (unexpected char '"' at 29; 28853)
[2023-08-28 20:18:16,852] {local_task_job.py:156} INFO - Task exited with return code 1
[2023-08-28 20:18:16,926] {local_task_job.py:273} INFO - 0 downstream tasks scheduled from follow-on schedule check
[2023-08-28 20:21:56,970] {taskinstance.py:1159} INFO - Dependencies all met for <TaskInstance: dados_climaticos.extrai_dados scheduled__2023-07-31T00:00:00+00:00 [queued]>
[2023-08-28 20:21:57,000] {taskinstance.py:1159} INFO - Dependencies all met for <TaskInstance: dados_climaticos.extrai_dados scheduled__2023-07-31T00:00:00+00:00 [queued]>
[2023-08-28 20:21:57,000] {taskinstance.py:1356} INFO - 
--------------------------------------------------------------------------------
[2023-08-28 20:21:57,001] {taskinstance.py:1357} INFO - Starting attempt 1 of 1
[2023-08-28 20:21:57,001] {taskinstance.py:1358} INFO - 
--------------------------------------------------------------------------------
[2023-08-28 20:21:57,043] {taskinstance.py:1377} INFO - Executing <Task(PythonOperator): extrai_dados> on 2023-07-31 00:00:00+00:00
[2023-08-28 20:21:57,099] {standard_task_runner.py:52} INFO - Started process 30657 to run task
[2023-08-28 20:21:57,118] {standard_task_runner.py:79} INFO - Running: ['airflow', 'tasks', 'run', 'dados_climaticos', 'extrai_dados', 'scheduled__2023-07-31T00:00:00+00:00', '--job-id', '26', '--raw', '--subdir', 'DAGS_FOLDER/dados_climaticos.py', '--cfg-path', '/tmp/tmpw8179fjb', '--error-file', '/tmp/tmp2nq4u5on']
[2023-08-28 20:21:57,125] {standard_task_runner.py:80} INFO - Job 26: Subtask extrai_dados
[2023-08-28 20:21:57,275] {task_command.py:370} INFO - Running <TaskInstance: dados_climaticos.extrai_dados scheduled__2023-07-31T00:00:00+00:00 [running]> on host FelipeBreve-PC.localdomain
[2023-08-28 20:21:57,368] {taskinstance.py:1889} ERROR - Task failed with exception
Traceback (most recent call last):
  File "/home/felipe/airflow/venv/lib/python3.9/site-packages/airflow/models/taskinstance.py", line 1451, in _run_raw_task
    self._execute_task_with_callbacks(context, test_mode)
  File "/home/felipe/airflow/venv/lib/python3.9/site-packages/airflow/models/taskinstance.py", line 1555, in _execute_task_with_callbacks
    task_orig = self.render_templates(context=context)
  File "/home/felipe/airflow/venv/lib/python3.9/site-packages/airflow/models/taskinstance.py", line 2212, in render_templates
    rendered_task = self.task.render_template_fields(context)
  File "/home/felipe/airflow/venv/lib/python3.9/site-packages/airflow/models/baseoperator.py", line 1185, in render_template_fields
    self._do_render_template_fields(self, self.template_fields, context, jinja_env, set())
  File "/home/felipe/airflow/venv/lib/python3.9/site-packages/airflow/utils/session.py", line 71, in wrapper
    return func(*args, session=session, **kwargs)
  File "/home/felipe/airflow/venv/lib/python3.9/site-packages/airflow/models/abstractoperator.py", line 344, in _do_render_template_fields
    rendered_content = self.render_template(
  File "/home/felipe/airflow/venv/lib/python3.9/site-packages/airflow/models/abstractoperator.py", line 404, in render_template
    return {key: self.render_template(value, context, jinja_env) for key, value in value.items()}
  File "/home/felipe/airflow/venv/lib/python3.9/site-packages/airflow/models/abstractoperator.py", line 404, in <dictcomp>
    return {key: self.render_template(value, context, jinja_env) for key, value in value.items()}
  File "/home/felipe/airflow/venv/lib/python3.9/site-packages/airflow/models/abstractoperator.py", line 387, in render_template
    template = jinja_env.from_string(value)
  File "/home/felipe/airflow/venv/lib/python3.9/site-packages/jinja2/environment.py", line 1092, in from_string
    return cls.from_code(self, self.compile(source), gs, None)
  File "/home/felipe/airflow/venv/lib/python3.9/site-packages/jinja2/environment.py", line 757, in compile
    self.handle_exception(source=source_hint)
  File "/home/felipe/airflow/venv/lib/python3.9/site-packages/jinja2/environment.py", line 925, in handle_exception
    raise rewrite_traceback_stack(source=source)
  File "<unknown>", line 1, in template
jinja2.exceptions.TemplateSyntaxError: unexpected char '"' at 29
[2023-08-28 20:21:57,395] {taskinstance.py:1395} INFO - Marking task as FAILED. dag_id=dados_climaticos, task_id=extrai_dados, execution_date=20230731T000000, start_date=20230828T232156, end_date=20230828T232157
[2023-08-28 20:21:57,420] {standard_task_runner.py:92} ERROR - Failed to execute job 26 for task extrai_dados (unexpected char '"' at 29; 30657)
[2023-08-28 20:21:57,459] {local_task_job.py:156} INFO - Task exited with return code 1
[2023-08-28 20:21:57,527] {local_task_job.py:273} INFO - 0 downstream tasks scheduled from follow-on schedule check
[2023-08-28 20:25:43,366] {taskinstance.py:1159} INFO - Dependencies all met for <TaskInstance: dados_climaticos.extrai_dados scheduled__2023-07-31T00:00:00+00:00 [queued]>
[2023-08-28 20:25:43,411] {taskinstance.py:1159} INFO - Dependencies all met for <TaskInstance: dados_climaticos.extrai_dados scheduled__2023-07-31T00:00:00+00:00 [queued]>
[2023-08-28 20:25:43,416] {taskinstance.py:1356} INFO - 
--------------------------------------------------------------------------------
[2023-08-28 20:25:43,416] {taskinstance.py:1357} INFO - Starting attempt 1 of 1
[2023-08-28 20:25:43,416] {taskinstance.py:1358} INFO - 
--------------------------------------------------------------------------------
[2023-08-28 20:25:43,474] {taskinstance.py:1377} INFO - Executing <Task(PythonOperator): extrai_dados> on 2023-07-31 00:00:00+00:00
[2023-08-28 20:25:43,524] {standard_task_runner.py:52} INFO - Started process 32207 to run task
[2023-08-28 20:25:43,544] {standard_task_runner.py:79} INFO - Running: ['airflow', 'tasks', 'run', 'dados_climaticos', 'extrai_dados', 'scheduled__2023-07-31T00:00:00+00:00', '--job-id', '26', '--raw', '--subdir', 'DAGS_FOLDER/dados_climaticos.py', '--cfg-path', '/tmp/tmp6vf5fcp7', '--error-file', '/tmp/tmp4u8dowc7']
[2023-08-28 20:25:43,553] {standard_task_runner.py:80} INFO - Job 26: Subtask extrai_dados
[2023-08-28 20:25:43,765] {task_command.py:370} INFO - Running <TaskInstance: dados_climaticos.extrai_dados scheduled__2023-07-31T00:00:00+00:00 [running]> on host FelipeBreve-PC.localdomain
[2023-08-28 20:25:43,871] {taskinstance.py:1889} ERROR - Task failed with exception
Traceback (most recent call last):
  File "/home/felipe/airflow/venv/lib/python3.9/site-packages/airflow/models/taskinstance.py", line 1451, in _run_raw_task
    self._execute_task_with_callbacks(context, test_mode)
  File "/home/felipe/airflow/venv/lib/python3.9/site-packages/airflow/models/taskinstance.py", line 1555, in _execute_task_with_callbacks
    task_orig = self.render_templates(context=context)
  File "/home/felipe/airflow/venv/lib/python3.9/site-packages/airflow/models/taskinstance.py", line 2212, in render_templates
    rendered_task = self.task.render_template_fields(context)
  File "/home/felipe/airflow/venv/lib/python3.9/site-packages/airflow/models/baseoperator.py", line 1185, in render_template_fields
    self._do_render_template_fields(self, self.template_fields, context, jinja_env, set())
  File "/home/felipe/airflow/venv/lib/python3.9/site-packages/airflow/utils/session.py", line 71, in wrapper
    return func(*args, session=session, **kwargs)
  File "/home/felipe/airflow/venv/lib/python3.9/site-packages/airflow/models/abstractoperator.py", line 344, in _do_render_template_fields
    rendered_content = self.render_template(
  File "/home/felipe/airflow/venv/lib/python3.9/site-packages/airflow/models/abstractoperator.py", line 404, in render_template
    return {key: self.render_template(value, context, jinja_env) for key, value in value.items()}
  File "/home/felipe/airflow/venv/lib/python3.9/site-packages/airflow/models/abstractoperator.py", line 404, in <dictcomp>
    return {key: self.render_template(value, context, jinja_env) for key, value in value.items()}
  File "/home/felipe/airflow/venv/lib/python3.9/site-packages/airflow/models/abstractoperator.py", line 387, in render_template
    template = jinja_env.from_string(value)
  File "/home/felipe/airflow/venv/lib/python3.9/site-packages/jinja2/environment.py", line 1092, in from_string
    return cls.from_code(self, self.compile(source), gs, None)
  File "/home/felipe/airflow/venv/lib/python3.9/site-packages/jinja2/environment.py", line 757, in compile
    self.handle_exception(source=source_hint)
  File "/home/felipe/airflow/venv/lib/python3.9/site-packages/jinja2/environment.py", line 925, in handle_exception
    raise rewrite_traceback_stack(source=source)
  File "<unknown>", line 1, in template
jinja2.exceptions.TemplateSyntaxError: unexpected char '"' at 29
[2023-08-28 20:25:43,906] {taskinstance.py:1395} INFO - Marking task as FAILED. dag_id=dados_climaticos, task_id=extrai_dados, execution_date=20230731T000000, start_date=20230828T232543, end_date=20230828T232543
[2023-08-28 20:25:43,953] {standard_task_runner.py:92} ERROR - Failed to execute job 26 for task extrai_dados (unexpected char '"' at 29; 32207)
[2023-08-28 20:25:43,984] {local_task_job.py:156} INFO - Task exited with return code 1
[2023-08-28 20:25:44,066] {local_task_job.py:273} INFO - 0 downstream tasks scheduled from follow-on schedule check
[2023-08-28 20:27:59,890] {taskinstance.py:1159} INFO - Dependencies all met for <TaskInstance: dados_climaticos.extrai_dados scheduled__2023-07-31T00:00:00+00:00 [queued]>
[2023-08-28 20:27:59,922] {taskinstance.py:1159} INFO - Dependencies all met for <TaskInstance: dados_climaticos.extrai_dados scheduled__2023-07-31T00:00:00+00:00 [queued]>
[2023-08-28 20:27:59,922] {taskinstance.py:1356} INFO - 
--------------------------------------------------------------------------------
[2023-08-28 20:27:59,922] {taskinstance.py:1357} INFO - Starting attempt 1 of 1
[2023-08-28 20:27:59,923] {taskinstance.py:1358} INFO - 
--------------------------------------------------------------------------------
[2023-08-28 20:27:59,968] {taskinstance.py:1377} INFO - Executing <Task(PythonOperator): extrai_dados> on 2023-07-31 00:00:00+00:00
[2023-08-28 20:28:00,032] {standard_task_runner.py:52} INFO - Started process 451 to run task
[2023-08-28 20:28:00,056] {standard_task_runner.py:79} INFO - Running: ['airflow', 'tasks', 'run', 'dados_climaticos', 'extrai_dados', 'scheduled__2023-07-31T00:00:00+00:00', '--job-id', '26', '--raw', '--subdir', 'DAGS_FOLDER/dados_climaticos.py', '--cfg-path', '/tmp/tmp8u0diths', '--error-file', '/tmp/tmpkdd687lr']
[2023-08-28 20:28:00,063] {standard_task_runner.py:80} INFO - Job 26: Subtask extrai_dados
[2023-08-28 20:28:00,222] {task_command.py:370} INFO - Running <TaskInstance: dados_climaticos.extrai_dados scheduled__2023-07-31T00:00:00+00:00 [running]> on host FelipeBreve-PC.localdomain
[2023-08-28 20:28:00,303] {taskinstance.py:1889} ERROR - Task failed with exception
Traceback (most recent call last):
  File "/home/felipe/airflow/venv/lib/python3.9/site-packages/airflow/models/taskinstance.py", line 1451, in _run_raw_task
    self._execute_task_with_callbacks(context, test_mode)
  File "/home/felipe/airflow/venv/lib/python3.9/site-packages/airflow/models/taskinstance.py", line 1555, in _execute_task_with_callbacks
    task_orig = self.render_templates(context=context)
  File "/home/felipe/airflow/venv/lib/python3.9/site-packages/airflow/models/taskinstance.py", line 2212, in render_templates
    rendered_task = self.task.render_template_fields(context)
  File "/home/felipe/airflow/venv/lib/python3.9/site-packages/airflow/models/baseoperator.py", line 1185, in render_template_fields
    self._do_render_template_fields(self, self.template_fields, context, jinja_env, set())
  File "/home/felipe/airflow/venv/lib/python3.9/site-packages/airflow/utils/session.py", line 71, in wrapper
    return func(*args, session=session, **kwargs)
  File "/home/felipe/airflow/venv/lib/python3.9/site-packages/airflow/models/abstractoperator.py", line 344, in _do_render_template_fields
    rendered_content = self.render_template(
  File "/home/felipe/airflow/venv/lib/python3.9/site-packages/airflow/models/abstractoperator.py", line 404, in render_template
    return {key: self.render_template(value, context, jinja_env) for key, value in value.items()}
  File "/home/felipe/airflow/venv/lib/python3.9/site-packages/airflow/models/abstractoperator.py", line 404, in <dictcomp>
    return {key: self.render_template(value, context, jinja_env) for key, value in value.items()}
  File "/home/felipe/airflow/venv/lib/python3.9/site-packages/airflow/models/abstractoperator.py", line 387, in render_template
    template = jinja_env.from_string(value)
  File "/home/felipe/airflow/venv/lib/python3.9/site-packages/jinja2/environment.py", line 1092, in from_string
    return cls.from_code(self, self.compile(source), gs, None)
  File "/home/felipe/airflow/venv/lib/python3.9/site-packages/jinja2/environment.py", line 757, in compile
    self.handle_exception(source=source_hint)
  File "/home/felipe/airflow/venv/lib/python3.9/site-packages/jinja2/environment.py", line 925, in handle_exception
    raise rewrite_traceback_stack(source=source)
  File "<unknown>", line 1, in template
jinja2.exceptions.TemplateSyntaxError: unexpected char '"' at 29
[2023-08-28 20:28:00,333] {taskinstance.py:1395} INFO - Marking task as FAILED. dag_id=dados_climaticos, task_id=extrai_dados, execution_date=20230731T000000, start_date=20230828T232759, end_date=20230828T232800
[2023-08-28 20:28:00,357] {standard_task_runner.py:92} ERROR - Failed to execute job 26 for task extrai_dados (unexpected char '"' at 29; 451)
[2023-08-28 20:28:00,376] {local_task_job.py:156} INFO - Task exited with return code 1
[2023-08-28 20:28:00,436] {local_task_job.py:273} INFO - 0 downstream tasks scheduled from follow-on schedule check
[2023-08-28 20:30:17,320] {taskinstance.py:1159} INFO - Dependencies all met for <TaskInstance: dados_climaticos.extrai_dados scheduled__2023-07-31T00:00:00+00:00 [queued]>
[2023-08-28 20:30:17,341] {taskinstance.py:1159} INFO - Dependencies all met for <TaskInstance: dados_climaticos.extrai_dados scheduled__2023-07-31T00:00:00+00:00 [queued]>
[2023-08-28 20:30:17,342] {taskinstance.py:1356} INFO - 
--------------------------------------------------------------------------------
[2023-08-28 20:30:17,342] {taskinstance.py:1357} INFO - Starting attempt 1 of 1
[2023-08-28 20:30:17,342] {taskinstance.py:1358} INFO - 
--------------------------------------------------------------------------------
[2023-08-28 20:30:17,379] {taskinstance.py:1377} INFO - Executing <Task(PythonOperator): extrai_dados> on 2023-07-31 00:00:00+00:00
[2023-08-28 20:30:17,435] {standard_task_runner.py:52} INFO - Started process 1953 to run task
[2023-08-28 20:30:17,468] {standard_task_runner.py:79} INFO - Running: ['airflow', 'tasks', 'run', 'dados_climaticos', 'extrai_dados', 'scheduled__2023-07-31T00:00:00+00:00', '--job-id', '26', '--raw', '--subdir', 'DAGS_FOLDER/dados_climaticos.py', '--cfg-path', '/tmp/tmpp65iy7jp', '--error-file', '/tmp/tmp2mvi69xt']
[2023-08-28 20:30:17,481] {standard_task_runner.py:80} INFO - Job 26: Subtask extrai_dados
[2023-08-28 20:30:17,766] {task_command.py:370} INFO - Running <TaskInstance: dados_climaticos.extrai_dados scheduled__2023-07-31T00:00:00+00:00 [running]> on host FelipeBreve-PC.localdomain
[2023-08-28 20:30:17,849] {taskinstance.py:1889} ERROR - Task failed with exception
Traceback (most recent call last):
  File "/home/felipe/airflow/venv/lib/python3.9/site-packages/airflow/models/taskinstance.py", line 1451, in _run_raw_task
    self._execute_task_with_callbacks(context, test_mode)
  File "/home/felipe/airflow/venv/lib/python3.9/site-packages/airflow/models/taskinstance.py", line 1555, in _execute_task_with_callbacks
    task_orig = self.render_templates(context=context)
  File "/home/felipe/airflow/venv/lib/python3.9/site-packages/airflow/models/taskinstance.py", line 2212, in render_templates
    rendered_task = self.task.render_template_fields(context)
  File "/home/felipe/airflow/venv/lib/python3.9/site-packages/airflow/models/baseoperator.py", line 1185, in render_template_fields
    self._do_render_template_fields(self, self.template_fields, context, jinja_env, set())
  File "/home/felipe/airflow/venv/lib/python3.9/site-packages/airflow/utils/session.py", line 71, in wrapper
    return func(*args, session=session, **kwargs)
  File "/home/felipe/airflow/venv/lib/python3.9/site-packages/airflow/models/abstractoperator.py", line 344, in _do_render_template_fields
    rendered_content = self.render_template(
  File "/home/felipe/airflow/venv/lib/python3.9/site-packages/airflow/models/abstractoperator.py", line 404, in render_template
    return {key: self.render_template(value, context, jinja_env) for key, value in value.items()}
  File "/home/felipe/airflow/venv/lib/python3.9/site-packages/airflow/models/abstractoperator.py", line 404, in <dictcomp>
    return {key: self.render_template(value, context, jinja_env) for key, value in value.items()}
  File "/home/felipe/airflow/venv/lib/python3.9/site-packages/airflow/models/abstractoperator.py", line 387, in render_template
    template = jinja_env.from_string(value)
  File "/home/felipe/airflow/venv/lib/python3.9/site-packages/jinja2/environment.py", line 1092, in from_string
    return cls.from_code(self, self.compile(source), gs, None)
  File "/home/felipe/airflow/venv/lib/python3.9/site-packages/jinja2/environment.py", line 757, in compile
    self.handle_exception(source=source_hint)
  File "/home/felipe/airflow/venv/lib/python3.9/site-packages/jinja2/environment.py", line 925, in handle_exception
    raise rewrite_traceback_stack(source=source)
  File "<unknown>", line 1, in template
jinja2.exceptions.TemplateSyntaxError: unexpected char '"' at 29
[2023-08-28 20:30:17,894] {taskinstance.py:1395} INFO - Marking task as FAILED. dag_id=dados_climaticos, task_id=extrai_dados, execution_date=20230731T000000, start_date=20230828T233017, end_date=20230828T233017
[2023-08-28 20:30:18,053] {standard_task_runner.py:92} ERROR - Failed to execute job 26 for task extrai_dados (unexpected char '"' at 29; 1953)
[2023-08-28 20:30:18,068] {local_task_job.py:156} INFO - Task exited with return code 1
[2023-08-28 20:30:18,187] {taskinstance.py:1395} INFO - Marking task as FAILED. dag_id=dados_climaticos, task_id=extrai_dados, execution_date=20230731T000000, start_date=20230828T233017, end_date=20230828T233018
[2023-08-28 20:30:18,336] {local_task_job.py:273} INFO - 0 downstream tasks scheduled from follow-on schedule check
[2023-08-28 20:40:31,973] {taskinstance.py:1159} INFO - Dependencies all met for <TaskInstance: dados_climaticos.extrai_dados scheduled__2023-07-31T00:00:00+00:00 [queued]>
[2023-08-28 20:40:32,033] {taskinstance.py:1159} INFO - Dependencies all met for <TaskInstance: dados_climaticos.extrai_dados scheduled__2023-07-31T00:00:00+00:00 [queued]>
[2023-08-28 20:40:32,034] {taskinstance.py:1356} INFO - 
--------------------------------------------------------------------------------
[2023-08-28 20:40:32,034] {taskinstance.py:1357} INFO - Starting attempt 1 of 1
[2023-08-28 20:40:32,034] {taskinstance.py:1358} INFO - 
--------------------------------------------------------------------------------
[2023-08-28 20:40:32,115] {taskinstance.py:1377} INFO - Executing <Task(PythonOperator): extrai_dados> on 2023-07-31 00:00:00+00:00
[2023-08-28 20:40:32,199] {standard_task_runner.py:52} INFO - Started process 4713 to run task
[2023-08-28 20:40:32,232] {standard_task_runner.py:79} INFO - Running: ['airflow', 'tasks', 'run', 'dados_climaticos', 'extrai_dados', 'scheduled__2023-07-31T00:00:00+00:00', '--job-id', '26', '--raw', '--subdir', 'DAGS_FOLDER/dados_climaticos.py', '--cfg-path', '/tmp/tmp28bxmphs', '--error-file', '/tmp/tmpahtpwg4b']
[2023-08-28 20:40:32,239] {standard_task_runner.py:80} INFO - Job 26: Subtask extrai_dados
[2023-08-28 20:40:32,556] {task_command.py:370} INFO - Running <TaskInstance: dados_climaticos.extrai_dados scheduled__2023-07-31T00:00:00+00:00 [running]> on host FelipeBreve-PC.localdomain
[2023-08-28 20:40:32,851] {taskinstance.py:1569} INFO - Exporting the following env vars:
AIRFLOW_CTX_DAG_OWNER=airflow
AIRFLOW_CTX_DAG_ID=dados_climaticos
AIRFLOW_CTX_TASK_ID=extrai_dados
AIRFLOW_CTX_EXECUTION_DATE=2023-07-31T00:00:00+00:00
AIRFLOW_CTX_TRY_NUMBER=1
AIRFLOW_CTX_DAG_RUN_ID=scheduled__2023-07-31T00:00:00+00:00
[2023-08-28 20:40:34,030] {python.py:173} INFO - Done. Returned value was: None
[2023-08-28 20:40:34,065] {taskinstance.py:1395} INFO - Marking task as SUCCESS. dag_id=dados_climaticos, task_id=extrai_dados, execution_date=20230731T000000, start_date=20230828T234031, end_date=20230828T234034
[2023-08-28 20:40:34,105] {local_task_job.py:156} INFO - Task exited with return code 0
[2023-08-28 20:40:34,214] {local_task_job.py:273} INFO - 0 downstream tasks scheduled from follow-on schedule check
