[2023-08-28 20:09:31,800] {taskinstance.py:1159} INFO - Dependencies all met for <TaskInstance: dados_climaticos.extrai_dados scheduled__2023-08-07T00:00:00+00:00 [queued]>
[2023-08-28 20:09:31,846] {taskinstance.py:1159} INFO - Dependencies all met for <TaskInstance: dados_climaticos.extrai_dados scheduled__2023-08-07T00:00:00+00:00 [queued]>
[2023-08-28 20:09:31,847] {taskinstance.py:1356} INFO - 
--------------------------------------------------------------------------------
[2023-08-28 20:09:31,848] {taskinstance.py:1357} INFO - Starting attempt 1 of 1
[2023-08-28 20:09:31,848] {taskinstance.py:1358} INFO - 
--------------------------------------------------------------------------------
[2023-08-28 20:09:31,943] {taskinstance.py:1377} INFO - Executing <Task(PythonOperator): extrai_dados> on 2023-08-07 00:00:00+00:00
[2023-08-28 20:09:32,047] {standard_task_runner.py:52} INFO - Started process 25462 to run task
[2023-08-28 20:09:32,096] {standard_task_runner.py:79} INFO - Running: ['airflow', 'tasks', 'run', 'dados_climaticos', 'extrai_dados', 'scheduled__2023-08-07T00:00:00+00:00', '--job-id', '16', '--raw', '--subdir', 'DAGS_FOLDER/dados_climaticos.py', '--cfg-path', '/tmp/tmpz5841hrg', '--error-file', '/tmp/tmp9imui3rl']
[2023-08-28 20:09:32,111] {standard_task_runner.py:80} INFO - Job 16: Subtask extrai_dados
[2023-08-28 20:09:32,493] {task_command.py:370} INFO - Running <TaskInstance: dados_climaticos.extrai_dados scheduled__2023-08-07T00:00:00+00:00 [running]> on host FelipeBreve-PC.localdomain
[2023-08-28 20:09:32,620] {taskinstance.py:1889} ERROR - Task failed with exception
Traceback (most recent call last):
  File "/home/felipe/airflow/venv/lib/python3.9/site-packages/airflow/models/taskinstance.py", line 1451, in _run_raw_task
    self._execute_task_with_callbacks(context, test_mode)
  File "/home/felipe/airflow/venv/lib/python3.9/site-packages/airflow/models/taskinstance.py", line 1555, in _execute_task_with_callbacks
    task_orig = self.render_templates(context=context)
  File "/home/felipe/airflow/venv/lib/python3.9/site-packages/airflow/models/taskinstance.py", line 2212, in render_templates
    rendered_task = self.task.render_template_fields(context)
  File "/home/felipe/airflow/venv/lib/python3.9/site-packages/airflow/models/baseoperator.py", line 1185, in render_template_fields
    self._do_render_template_fields(self, self.template_fields, context, jinja_env, set())
  File "/home/felipe/airflow/venv/lib/python3.9/site-packages/airflow/utils/session.py", line 71, in wrapper
    return func(*args, session=session, **kwargs)
  File "/home/felipe/airflow/venv/lib/python3.9/site-packages/airflow/models/abstractoperator.py", line 344, in _do_render_template_fields
    rendered_content = self.render_template(
  File "/home/felipe/airflow/venv/lib/python3.9/site-packages/airflow/models/abstractoperator.py", line 404, in render_template
    return {key: self.render_template(value, context, jinja_env) for key, value in value.items()}
  File "/home/felipe/airflow/venv/lib/python3.9/site-packages/airflow/models/abstractoperator.py", line 404, in <dictcomp>
    return {key: self.render_template(value, context, jinja_env) for key, value in value.items()}
  File "/home/felipe/airflow/venv/lib/python3.9/site-packages/airflow/models/abstractoperator.py", line 387, in render_template
    template = jinja_env.from_string(value)
  File "/home/felipe/airflow/venv/lib/python3.9/site-packages/jinja2/environment.py", line 1092, in from_string
    return cls.from_code(self, self.compile(source), gs, None)
  File "/home/felipe/airflow/venv/lib/python3.9/site-packages/jinja2/environment.py", line 757, in compile
    self.handle_exception(source=source_hint)
  File "/home/felipe/airflow/venv/lib/python3.9/site-packages/jinja2/environment.py", line 925, in handle_exception
    raise rewrite_traceback_stack(source=source)
  File "<unknown>", line 1, in template
jinja2.exceptions.TemplateSyntaxError: unexpected char '"' at 29
[2023-08-28 20:09:32,678] {taskinstance.py:1395} INFO - Marking task as FAILED. dag_id=dados_climaticos, task_id=extrai_dados, execution_date=20230807T000000, start_date=20230828T230931, end_date=20230828T230932
[2023-08-28 20:09:32,762] {standard_task_runner.py:92} ERROR - Failed to execute job 16 for task extrai_dados (unexpected char '"' at 29; 25462)
[2023-08-28 20:09:32,814] {local_task_job.py:156} INFO - Task exited with return code 1
[2023-08-28 20:09:33,048] {local_task_job.py:273} INFO - 0 downstream tasks scheduled from follow-on schedule check
[2023-08-28 20:18:36,047] {taskinstance.py:1159} INFO - Dependencies all met for <TaskInstance: dados_climaticos.extrai_dados scheduled__2023-08-07T00:00:00+00:00 [queued]>
[2023-08-28 20:18:36,069] {taskinstance.py:1159} INFO - Dependencies all met for <TaskInstance: dados_climaticos.extrai_dados scheduled__2023-08-07T00:00:00+00:00 [queued]>
[2023-08-28 20:18:36,069] {taskinstance.py:1356} INFO - 
--------------------------------------------------------------------------------
[2023-08-28 20:18:36,069] {taskinstance.py:1357} INFO - Starting attempt 1 of 1
[2023-08-28 20:18:36,069] {taskinstance.py:1358} INFO - 
--------------------------------------------------------------------------------
[2023-08-28 20:18:36,108] {taskinstance.py:1377} INFO - Executing <Task(PythonOperator): extrai_dados> on 2023-08-07 00:00:00+00:00
[2023-08-28 20:18:36,162] {standard_task_runner.py:52} INFO - Started process 29075 to run task
[2023-08-28 20:18:36,179] {standard_task_runner.py:79} INFO - Running: ['airflow', 'tasks', 'run', 'dados_climaticos', 'extrai_dados', 'scheduled__2023-08-07T00:00:00+00:00', '--job-id', '28', '--raw', '--subdir', 'DAGS_FOLDER/dados_climaticos.py', '--cfg-path', '/tmp/tmpc732meby', '--error-file', '/tmp/tmp381igxiz']
[2023-08-28 20:18:36,184] {standard_task_runner.py:80} INFO - Job 28: Subtask extrai_dados
[2023-08-28 20:18:36,314] {task_command.py:370} INFO - Running <TaskInstance: dados_climaticos.extrai_dados scheduled__2023-08-07T00:00:00+00:00 [running]> on host FelipeBreve-PC.localdomain
[2023-08-28 20:18:36,379] {taskinstance.py:1889} ERROR - Task failed with exception
Traceback (most recent call last):
  File "/home/felipe/airflow/venv/lib/python3.9/site-packages/airflow/models/taskinstance.py", line 1451, in _run_raw_task
    self._execute_task_with_callbacks(context, test_mode)
  File "/home/felipe/airflow/venv/lib/python3.9/site-packages/airflow/models/taskinstance.py", line 1555, in _execute_task_with_callbacks
    task_orig = self.render_templates(context=context)
  File "/home/felipe/airflow/venv/lib/python3.9/site-packages/airflow/models/taskinstance.py", line 2212, in render_templates
    rendered_task = self.task.render_template_fields(context)
  File "/home/felipe/airflow/venv/lib/python3.9/site-packages/airflow/models/baseoperator.py", line 1185, in render_template_fields
    self._do_render_template_fields(self, self.template_fields, context, jinja_env, set())
  File "/home/felipe/airflow/venv/lib/python3.9/site-packages/airflow/utils/session.py", line 71, in wrapper
    return func(*args, session=session, **kwargs)
  File "/home/felipe/airflow/venv/lib/python3.9/site-packages/airflow/models/abstractoperator.py", line 344, in _do_render_template_fields
    rendered_content = self.render_template(
  File "/home/felipe/airflow/venv/lib/python3.9/site-packages/airflow/models/abstractoperator.py", line 404, in render_template
    return {key: self.render_template(value, context, jinja_env) for key, value in value.items()}
  File "/home/felipe/airflow/venv/lib/python3.9/site-packages/airflow/models/abstractoperator.py", line 404, in <dictcomp>
    return {key: self.render_template(value, context, jinja_env) for key, value in value.items()}
  File "/home/felipe/airflow/venv/lib/python3.9/site-packages/airflow/models/abstractoperator.py", line 387, in render_template
    template = jinja_env.from_string(value)
  File "/home/felipe/airflow/venv/lib/python3.9/site-packages/jinja2/environment.py", line 1092, in from_string
    return cls.from_code(self, self.compile(source), gs, None)
  File "/home/felipe/airflow/venv/lib/python3.9/site-packages/jinja2/environment.py", line 757, in compile
    self.handle_exception(source=source_hint)
  File "/home/felipe/airflow/venv/lib/python3.9/site-packages/jinja2/environment.py", line 925, in handle_exception
    raise rewrite_traceback_stack(source=source)
  File "<unknown>", line 1, in template
jinja2.exceptions.TemplateSyntaxError: unexpected char '"' at 29
[2023-08-28 20:18:36,399] {taskinstance.py:1395} INFO - Marking task as FAILED. dag_id=dados_climaticos, task_id=extrai_dados, execution_date=20230807T000000, start_date=20230828T231836, end_date=20230828T231836
[2023-08-28 20:18:36,425] {standard_task_runner.py:92} ERROR - Failed to execute job 28 for task extrai_dados (unexpected char '"' at 29; 29075)
[2023-08-28 20:18:36,433] {local_task_job.py:156} INFO - Task exited with return code 1
[2023-08-28 20:18:36,493] {local_task_job.py:273} INFO - 0 downstream tasks scheduled from follow-on schedule check
[2023-08-28 20:22:15,375] {taskinstance.py:1159} INFO - Dependencies all met for <TaskInstance: dados_climaticos.extrai_dados scheduled__2023-08-07T00:00:00+00:00 [queued]>
[2023-08-28 20:22:15,398] {taskinstance.py:1159} INFO - Dependencies all met for <TaskInstance: dados_climaticos.extrai_dados scheduled__2023-08-07T00:00:00+00:00 [queued]>
[2023-08-28 20:22:15,399] {taskinstance.py:1356} INFO - 
--------------------------------------------------------------------------------
[2023-08-28 20:22:15,399] {taskinstance.py:1357} INFO - Starting attempt 1 of 1
[2023-08-28 20:22:15,399] {taskinstance.py:1358} INFO - 
--------------------------------------------------------------------------------
[2023-08-28 20:22:15,443] {taskinstance.py:1377} INFO - Executing <Task(PythonOperator): extrai_dados> on 2023-08-07 00:00:00+00:00
[2023-08-28 20:22:15,500] {standard_task_runner.py:52} INFO - Started process 30850 to run task
[2023-08-28 20:22:15,526] {standard_task_runner.py:79} INFO - Running: ['airflow', 'tasks', 'run', 'dados_climaticos', 'extrai_dados', 'scheduled__2023-08-07T00:00:00+00:00', '--job-id', '28', '--raw', '--subdir', 'DAGS_FOLDER/dados_climaticos.py', '--cfg-path', '/tmp/tmpjefjtc3y', '--error-file', '/tmp/tmpmh0zybx9']
[2023-08-28 20:22:15,533] {standard_task_runner.py:80} INFO - Job 28: Subtask extrai_dados
[2023-08-28 20:22:15,697] {task_command.py:370} INFO - Running <TaskInstance: dados_climaticos.extrai_dados scheduled__2023-08-07T00:00:00+00:00 [running]> on host FelipeBreve-PC.localdomain
[2023-08-28 20:22:15,762] {taskinstance.py:1889} ERROR - Task failed with exception
Traceback (most recent call last):
  File "/home/felipe/airflow/venv/lib/python3.9/site-packages/airflow/models/taskinstance.py", line 1451, in _run_raw_task
    self._execute_task_with_callbacks(context, test_mode)
  File "/home/felipe/airflow/venv/lib/python3.9/site-packages/airflow/models/taskinstance.py", line 1555, in _execute_task_with_callbacks
    task_orig = self.render_templates(context=context)
  File "/home/felipe/airflow/venv/lib/python3.9/site-packages/airflow/models/taskinstance.py", line 2212, in render_templates
    rendered_task = self.task.render_template_fields(context)
  File "/home/felipe/airflow/venv/lib/python3.9/site-packages/airflow/models/baseoperator.py", line 1185, in render_template_fields
    self._do_render_template_fields(self, self.template_fields, context, jinja_env, set())
  File "/home/felipe/airflow/venv/lib/python3.9/site-packages/airflow/utils/session.py", line 71, in wrapper
    return func(*args, session=session, **kwargs)
  File "/home/felipe/airflow/venv/lib/python3.9/site-packages/airflow/models/abstractoperator.py", line 344, in _do_render_template_fields
    rendered_content = self.render_template(
  File "/home/felipe/airflow/venv/lib/python3.9/site-packages/airflow/models/abstractoperator.py", line 404, in render_template
    return {key: self.render_template(value, context, jinja_env) for key, value in value.items()}
  File "/home/felipe/airflow/venv/lib/python3.9/site-packages/airflow/models/abstractoperator.py", line 404, in <dictcomp>
    return {key: self.render_template(value, context, jinja_env) for key, value in value.items()}
  File "/home/felipe/airflow/venv/lib/python3.9/site-packages/airflow/models/abstractoperator.py", line 387, in render_template
    template = jinja_env.from_string(value)
  File "/home/felipe/airflow/venv/lib/python3.9/site-packages/jinja2/environment.py", line 1092, in from_string
    return cls.from_code(self, self.compile(source), gs, None)
  File "/home/felipe/airflow/venv/lib/python3.9/site-packages/jinja2/environment.py", line 757, in compile
    self.handle_exception(source=source_hint)
  File "/home/felipe/airflow/venv/lib/python3.9/site-packages/jinja2/environment.py", line 925, in handle_exception
    raise rewrite_traceback_stack(source=source)
  File "<unknown>", line 1, in template
jinja2.exceptions.TemplateSyntaxError: unexpected char '"' at 29
[2023-08-28 20:22:15,780] {taskinstance.py:1395} INFO - Marking task as FAILED. dag_id=dados_climaticos, task_id=extrai_dados, execution_date=20230807T000000, start_date=20230828T232215, end_date=20230828T232215
[2023-08-28 20:22:15,804] {standard_task_runner.py:92} ERROR - Failed to execute job 28 for task extrai_dados (unexpected char '"' at 29; 30850)
[2023-08-28 20:22:15,819] {local_task_job.py:156} INFO - Task exited with return code 1
[2023-08-28 20:22:15,877] {local_task_job.py:273} INFO - 0 downstream tasks scheduled from follow-on schedule check
[2023-08-28 20:30:35,375] {taskinstance.py:1159} INFO - Dependencies all met for <TaskInstance: dados_climaticos.extrai_dados scheduled__2023-08-07T00:00:00+00:00 [queued]>
[2023-08-28 20:30:35,407] {taskinstance.py:1159} INFO - Dependencies all met for <TaskInstance: dados_climaticos.extrai_dados scheduled__2023-08-07T00:00:00+00:00 [queued]>
[2023-08-28 20:30:35,408] {taskinstance.py:1356} INFO - 
--------------------------------------------------------------------------------
[2023-08-28 20:30:35,408] {taskinstance.py:1357} INFO - Starting attempt 1 of 1
[2023-08-28 20:30:35,409] {taskinstance.py:1358} INFO - 
--------------------------------------------------------------------------------
[2023-08-28 20:30:35,461] {taskinstance.py:1377} INFO - Executing <Task(PythonOperator): extrai_dados> on 2023-08-07 00:00:00+00:00
[2023-08-28 20:30:35,524] {standard_task_runner.py:52} INFO - Started process 2156 to run task
[2023-08-28 20:30:35,552] {standard_task_runner.py:79} INFO - Running: ['airflow', 'tasks', 'run', 'dados_climaticos', 'extrai_dados', 'scheduled__2023-08-07T00:00:00+00:00', '--job-id', '28', '--raw', '--subdir', 'DAGS_FOLDER/dados_climaticos.py', '--cfg-path', '/tmp/tmphmjmxt_3', '--error-file', '/tmp/tmpjnh7gut3']
[2023-08-28 20:30:35,560] {standard_task_runner.py:80} INFO - Job 28: Subtask extrai_dados
[2023-08-28 20:30:35,764] {task_command.py:370} INFO - Running <TaskInstance: dados_climaticos.extrai_dados scheduled__2023-08-07T00:00:00+00:00 [running]> on host FelipeBreve-PC.localdomain
[2023-08-28 20:30:35,888] {taskinstance.py:1889} ERROR - Task failed with exception
Traceback (most recent call last):
  File "/home/felipe/airflow/venv/lib/python3.9/site-packages/airflow/models/taskinstance.py", line 1451, in _run_raw_task
    self._execute_task_with_callbacks(context, test_mode)
  File "/home/felipe/airflow/venv/lib/python3.9/site-packages/airflow/models/taskinstance.py", line 1555, in _execute_task_with_callbacks
    task_orig = self.render_templates(context=context)
  File "/home/felipe/airflow/venv/lib/python3.9/site-packages/airflow/models/taskinstance.py", line 2212, in render_templates
    rendered_task = self.task.render_template_fields(context)
  File "/home/felipe/airflow/venv/lib/python3.9/site-packages/airflow/models/baseoperator.py", line 1185, in render_template_fields
    self._do_render_template_fields(self, self.template_fields, context, jinja_env, set())
  File "/home/felipe/airflow/venv/lib/python3.9/site-packages/airflow/utils/session.py", line 71, in wrapper
    return func(*args, session=session, **kwargs)
  File "/home/felipe/airflow/venv/lib/python3.9/site-packages/airflow/models/abstractoperator.py", line 344, in _do_render_template_fields
    rendered_content = self.render_template(
  File "/home/felipe/airflow/venv/lib/python3.9/site-packages/airflow/models/abstractoperator.py", line 404, in render_template
    return {key: self.render_template(value, context, jinja_env) for key, value in value.items()}
  File "/home/felipe/airflow/venv/lib/python3.9/site-packages/airflow/models/abstractoperator.py", line 404, in <dictcomp>
    return {key: self.render_template(value, context, jinja_env) for key, value in value.items()}
  File "/home/felipe/airflow/venv/lib/python3.9/site-packages/airflow/models/abstractoperator.py", line 387, in render_template
    template = jinja_env.from_string(value)
  File "/home/felipe/airflow/venv/lib/python3.9/site-packages/jinja2/environment.py", line 1092, in from_string
    return cls.from_code(self, self.compile(source), gs, None)
  File "/home/felipe/airflow/venv/lib/python3.9/site-packages/jinja2/environment.py", line 757, in compile
    self.handle_exception(source=source_hint)
  File "/home/felipe/airflow/venv/lib/python3.9/site-packages/jinja2/environment.py", line 925, in handle_exception
    raise rewrite_traceback_stack(source=source)
  File "<unknown>", line 1, in template
jinja2.exceptions.TemplateSyntaxError: unexpected char '"' at 29
[2023-08-28 20:30:35,938] {taskinstance.py:1395} INFO - Marking task as FAILED. dag_id=dados_climaticos, task_id=extrai_dados, execution_date=20230807T000000, start_date=20230828T233035, end_date=20230828T233035
[2023-08-28 20:30:35,985] {standard_task_runner.py:92} ERROR - Failed to execute job 28 for task extrai_dados (unexpected char '"' at 29; 2156)
[2023-08-28 20:30:36,014] {local_task_job.py:156} INFO - Task exited with return code 1
[2023-08-28 20:30:36,135] {local_task_job.py:273} INFO - 0 downstream tasks scheduled from follow-on schedule check
[2023-08-28 20:40:54,399] {taskinstance.py:1159} INFO - Dependencies all met for <TaskInstance: dados_climaticos.extrai_dados scheduled__2023-08-07T00:00:00+00:00 [queued]>
[2023-08-28 20:40:54,426] {taskinstance.py:1159} INFO - Dependencies all met for <TaskInstance: dados_climaticos.extrai_dados scheduled__2023-08-07T00:00:00+00:00 [queued]>
[2023-08-28 20:40:54,426] {taskinstance.py:1356} INFO - 
--------------------------------------------------------------------------------
[2023-08-28 20:40:54,426] {taskinstance.py:1357} INFO - Starting attempt 1 of 1
[2023-08-28 20:40:54,427] {taskinstance.py:1358} INFO - 
--------------------------------------------------------------------------------
[2023-08-28 20:40:54,465] {taskinstance.py:1377} INFO - Executing <Task(PythonOperator): extrai_dados> on 2023-08-07 00:00:00+00:00
[2023-08-28 20:40:54,521] {standard_task_runner.py:52} INFO - Started process 4968 to run task
[2023-08-28 20:40:54,541] {standard_task_runner.py:79} INFO - Running: ['airflow', 'tasks', 'run', 'dados_climaticos', 'extrai_dados', 'scheduled__2023-08-07T00:00:00+00:00', '--job-id', '28', '--raw', '--subdir', 'DAGS_FOLDER/dados_climaticos.py', '--cfg-path', '/tmp/tmp_sy8yy83', '--error-file', '/tmp/tmpzpn78vly']
[2023-08-28 20:40:54,545] {standard_task_runner.py:80} INFO - Job 28: Subtask extrai_dados
[2023-08-28 20:40:54,712] {task_command.py:370} INFO - Running <TaskInstance: dados_climaticos.extrai_dados scheduled__2023-08-07T00:00:00+00:00 [running]> on host FelipeBreve-PC.localdomain
[2023-08-28 20:40:54,876] {taskinstance.py:1569} INFO - Exporting the following env vars:
AIRFLOW_CTX_DAG_OWNER=airflow
AIRFLOW_CTX_DAG_ID=dados_climaticos
AIRFLOW_CTX_TASK_ID=extrai_dados
AIRFLOW_CTX_EXECUTION_DATE=2023-08-07T00:00:00+00:00
AIRFLOW_CTX_TRY_NUMBER=1
AIRFLOW_CTX_DAG_RUN_ID=scheduled__2023-08-07T00:00:00+00:00
[2023-08-28 20:40:55,910] {python.py:173} INFO - Done. Returned value was: None
[2023-08-28 20:40:55,946] {taskinstance.py:1395} INFO - Marking task as SUCCESS. dag_id=dados_climaticos, task_id=extrai_dados, execution_date=20230807T000000, start_date=20230828T234054, end_date=20230828T234055
[2023-08-28 20:40:56,015] {local_task_job.py:156} INFO - Task exited with return code 0
[2023-08-28 20:40:56,098] {local_task_job.py:273} INFO - 0 downstream tasks scheduled from follow-on schedule check
