[2023-08-28 20:10:10,992] {taskinstance.py:1159} INFO - Dependencies all met for <TaskInstance: dados_climaticos.extrai_dados scheduled__2023-08-21T00:00:00+00:00 [queued]>
[2023-08-28 20:10:11,014] {taskinstance.py:1159} INFO - Dependencies all met for <TaskInstance: dados_climaticos.extrai_dados scheduled__2023-08-21T00:00:00+00:00 [queued]>
[2023-08-28 20:10:11,015] {taskinstance.py:1356} INFO - 
--------------------------------------------------------------------------------
[2023-08-28 20:10:11,015] {taskinstance.py:1357} INFO - Starting attempt 1 of 1
[2023-08-28 20:10:11,016] {taskinstance.py:1358} INFO - 
--------------------------------------------------------------------------------
[2023-08-28 20:10:11,057] {taskinstance.py:1377} INFO - Executing <Task(PythonOperator): extrai_dados> on 2023-08-21 00:00:00+00:00
[2023-08-28 20:10:11,124] {standard_task_runner.py:52} INFO - Started process 25914 to run task
[2023-08-28 20:10:11,149] {standard_task_runner.py:79} INFO - Running: ['airflow', 'tasks', 'run', 'dados_climaticos', 'extrai_dados', 'scheduled__2023-08-21T00:00:00+00:00', '--job-id', '19', '--raw', '--subdir', 'DAGS_FOLDER/dados_climaticos.py', '--cfg-path', '/tmp/tmpls24xshj', '--error-file', '/tmp/tmpy4yw5s5w']
[2023-08-28 20:10:11,156] {standard_task_runner.py:80} INFO - Job 19: Subtask extrai_dados
[2023-08-28 20:10:11,453] {task_command.py:370} INFO - Running <TaskInstance: dados_climaticos.extrai_dados scheduled__2023-08-21T00:00:00+00:00 [running]> on host FelipeBreve-PC.localdomain
[2023-08-28 20:10:11,564] {taskinstance.py:1889} ERROR - Task failed with exception
Traceback (most recent call last):
  File "/home/felipe/airflow/venv/lib/python3.9/site-packages/airflow/models/taskinstance.py", line 1451, in _run_raw_task
    self._execute_task_with_callbacks(context, test_mode)
  File "/home/felipe/airflow/venv/lib/python3.9/site-packages/airflow/models/taskinstance.py", line 1555, in _execute_task_with_callbacks
    task_orig = self.render_templates(context=context)
  File "/home/felipe/airflow/venv/lib/python3.9/site-packages/airflow/models/taskinstance.py", line 2212, in render_templates
    rendered_task = self.task.render_template_fields(context)
  File "/home/felipe/airflow/venv/lib/python3.9/site-packages/airflow/models/baseoperator.py", line 1185, in render_template_fields
    self._do_render_template_fields(self, self.template_fields, context, jinja_env, set())
  File "/home/felipe/airflow/venv/lib/python3.9/site-packages/airflow/utils/session.py", line 71, in wrapper
    return func(*args, session=session, **kwargs)
  File "/home/felipe/airflow/venv/lib/python3.9/site-packages/airflow/models/abstractoperator.py", line 344, in _do_render_template_fields
    rendered_content = self.render_template(
  File "/home/felipe/airflow/venv/lib/python3.9/site-packages/airflow/models/abstractoperator.py", line 404, in render_template
    return {key: self.render_template(value, context, jinja_env) for key, value in value.items()}
  File "/home/felipe/airflow/venv/lib/python3.9/site-packages/airflow/models/abstractoperator.py", line 404, in <dictcomp>
    return {key: self.render_template(value, context, jinja_env) for key, value in value.items()}
  File "/home/felipe/airflow/venv/lib/python3.9/site-packages/airflow/models/abstractoperator.py", line 387, in render_template
    template = jinja_env.from_string(value)
  File "/home/felipe/airflow/venv/lib/python3.9/site-packages/jinja2/environment.py", line 1092, in from_string
    return cls.from_code(self, self.compile(source), gs, None)
  File "/home/felipe/airflow/venv/lib/python3.9/site-packages/jinja2/environment.py", line 757, in compile
    self.handle_exception(source=source_hint)
  File "/home/felipe/airflow/venv/lib/python3.9/site-packages/jinja2/environment.py", line 925, in handle_exception
    raise rewrite_traceback_stack(source=source)
  File "<unknown>", line 1, in template
jinja2.exceptions.TemplateSyntaxError: unexpected char '"' at 29
[2023-08-28 20:10:11,588] {taskinstance.py:1395} INFO - Marking task as FAILED. dag_id=dados_climaticos, task_id=extrai_dados, execution_date=20230821T000000, start_date=20230828T231010, end_date=20230828T231011
[2023-08-28 20:10:11,621] {standard_task_runner.py:92} ERROR - Failed to execute job 19 for task extrai_dados (unexpected char '"' at 29; 25914)
[2023-08-28 20:10:11,648] {local_task_job.py:156} INFO - Task exited with return code 1
[2023-08-28 20:10:11,721] {local_task_job.py:273} INFO - 0 downstream tasks scheduled from follow-on schedule check
[2023-08-28 20:19:02,371] {taskinstance.py:1159} INFO - Dependencies all met for <TaskInstance: dados_climaticos.extrai_dados scheduled__2023-08-21T00:00:00+00:00 [queued]>
[2023-08-28 20:19:02,387] {taskinstance.py:1159} INFO - Dependencies all met for <TaskInstance: dados_climaticos.extrai_dados scheduled__2023-08-21T00:00:00+00:00 [queued]>
[2023-08-28 20:19:02,388] {taskinstance.py:1356} INFO - 
--------------------------------------------------------------------------------
[2023-08-28 20:19:02,389] {taskinstance.py:1357} INFO - Starting attempt 1 of 1
[2023-08-28 20:19:02,390] {taskinstance.py:1358} INFO - 
--------------------------------------------------------------------------------
[2023-08-28 20:19:02,419] {taskinstance.py:1377} INFO - Executing <Task(PythonOperator): extrai_dados> on 2023-08-21 00:00:00+00:00
[2023-08-28 20:19:02,462] {standard_task_runner.py:52} INFO - Started process 29385 to run task
[2023-08-28 20:19:02,478] {standard_task_runner.py:79} INFO - Running: ['airflow', 'tasks', 'run', 'dados_climaticos', 'extrai_dados', 'scheduled__2023-08-21T00:00:00+00:00', '--job-id', '31', '--raw', '--subdir', 'DAGS_FOLDER/dados_climaticos.py', '--cfg-path', '/tmp/tmp9_sej1b8', '--error-file', '/tmp/tmp89m9__rn']
[2023-08-28 20:19:02,483] {standard_task_runner.py:80} INFO - Job 31: Subtask extrai_dados
[2023-08-28 20:19:02,603] {task_command.py:370} INFO - Running <TaskInstance: dados_climaticos.extrai_dados scheduled__2023-08-21T00:00:00+00:00 [running]> on host FelipeBreve-PC.localdomain
[2023-08-28 20:19:02,671] {taskinstance.py:1889} ERROR - Task failed with exception
Traceback (most recent call last):
  File "/home/felipe/airflow/venv/lib/python3.9/site-packages/airflow/models/taskinstance.py", line 1451, in _run_raw_task
    self._execute_task_with_callbacks(context, test_mode)
  File "/home/felipe/airflow/venv/lib/python3.9/site-packages/airflow/models/taskinstance.py", line 1555, in _execute_task_with_callbacks
    task_orig = self.render_templates(context=context)
  File "/home/felipe/airflow/venv/lib/python3.9/site-packages/airflow/models/taskinstance.py", line 2212, in render_templates
    rendered_task = self.task.render_template_fields(context)
  File "/home/felipe/airflow/venv/lib/python3.9/site-packages/airflow/models/baseoperator.py", line 1185, in render_template_fields
    self._do_render_template_fields(self, self.template_fields, context, jinja_env, set())
  File "/home/felipe/airflow/venv/lib/python3.9/site-packages/airflow/utils/session.py", line 71, in wrapper
    return func(*args, session=session, **kwargs)
  File "/home/felipe/airflow/venv/lib/python3.9/site-packages/airflow/models/abstractoperator.py", line 344, in _do_render_template_fields
    rendered_content = self.render_template(
  File "/home/felipe/airflow/venv/lib/python3.9/site-packages/airflow/models/abstractoperator.py", line 404, in render_template
    return {key: self.render_template(value, context, jinja_env) for key, value in value.items()}
  File "/home/felipe/airflow/venv/lib/python3.9/site-packages/airflow/models/abstractoperator.py", line 404, in <dictcomp>
    return {key: self.render_template(value, context, jinja_env) for key, value in value.items()}
  File "/home/felipe/airflow/venv/lib/python3.9/site-packages/airflow/models/abstractoperator.py", line 387, in render_template
    template = jinja_env.from_string(value)
  File "/home/felipe/airflow/venv/lib/python3.9/site-packages/jinja2/environment.py", line 1092, in from_string
    return cls.from_code(self, self.compile(source), gs, None)
  File "/home/felipe/airflow/venv/lib/python3.9/site-packages/jinja2/environment.py", line 757, in compile
    self.handle_exception(source=source_hint)
  File "/home/felipe/airflow/venv/lib/python3.9/site-packages/jinja2/environment.py", line 925, in handle_exception
    raise rewrite_traceback_stack(source=source)
  File "<unknown>", line 1, in template
jinja2.exceptions.TemplateSyntaxError: unexpected char '"' at 29
[2023-08-28 20:19:02,691] {taskinstance.py:1395} INFO - Marking task as FAILED. dag_id=dados_climaticos, task_id=extrai_dados, execution_date=20230821T000000, start_date=20230828T231902, end_date=20230828T231902
[2023-08-28 20:19:02,716] {standard_task_runner.py:92} ERROR - Failed to execute job 31 for task extrai_dados (unexpected char '"' at 29; 29385)
[2023-08-28 20:19:02,728] {local_task_job.py:156} INFO - Task exited with return code 1
[2023-08-28 20:19:02,789] {local_task_job.py:273} INFO - 0 downstream tasks scheduled from follow-on schedule check
[2023-08-28 20:22:42,922] {taskinstance.py:1159} INFO - Dependencies all met for <TaskInstance: dados_climaticos.extrai_dados scheduled__2023-08-21T00:00:00+00:00 [queued]>
[2023-08-28 20:22:42,938] {taskinstance.py:1159} INFO - Dependencies all met for <TaskInstance: dados_climaticos.extrai_dados scheduled__2023-08-21T00:00:00+00:00 [queued]>
[2023-08-28 20:22:42,938] {taskinstance.py:1356} INFO - 
--------------------------------------------------------------------------------
[2023-08-28 20:22:42,938] {taskinstance.py:1357} INFO - Starting attempt 1 of 1
[2023-08-28 20:22:42,938] {taskinstance.py:1358} INFO - 
--------------------------------------------------------------------------------
[2023-08-28 20:22:42,972] {taskinstance.py:1377} INFO - Executing <Task(PythonOperator): extrai_dados> on 2023-08-21 00:00:00+00:00
[2023-08-28 20:22:43,022] {standard_task_runner.py:52} INFO - Started process 31162 to run task
[2023-08-28 20:22:43,040] {standard_task_runner.py:79} INFO - Running: ['airflow', 'tasks', 'run', 'dados_climaticos', 'extrai_dados', 'scheduled__2023-08-21T00:00:00+00:00', '--job-id', '31', '--raw', '--subdir', 'DAGS_FOLDER/dados_climaticos.py', '--cfg-path', '/tmp/tmpsvjt_3a8', '--error-file', '/tmp/tmp8ban7gu_']
[2023-08-28 20:22:43,045] {standard_task_runner.py:80} INFO - Job 31: Subtask extrai_dados
[2023-08-28 20:22:43,175] {task_command.py:370} INFO - Running <TaskInstance: dados_climaticos.extrai_dados scheduled__2023-08-21T00:00:00+00:00 [running]> on host FelipeBreve-PC.localdomain
[2023-08-28 20:22:43,241] {taskinstance.py:1889} ERROR - Task failed with exception
Traceback (most recent call last):
  File "/home/felipe/airflow/venv/lib/python3.9/site-packages/airflow/models/taskinstance.py", line 1451, in _run_raw_task
    self._execute_task_with_callbacks(context, test_mode)
  File "/home/felipe/airflow/venv/lib/python3.9/site-packages/airflow/models/taskinstance.py", line 1555, in _execute_task_with_callbacks
    task_orig = self.render_templates(context=context)
  File "/home/felipe/airflow/venv/lib/python3.9/site-packages/airflow/models/taskinstance.py", line 2212, in render_templates
    rendered_task = self.task.render_template_fields(context)
  File "/home/felipe/airflow/venv/lib/python3.9/site-packages/airflow/models/baseoperator.py", line 1185, in render_template_fields
    self._do_render_template_fields(self, self.template_fields, context, jinja_env, set())
  File "/home/felipe/airflow/venv/lib/python3.9/site-packages/airflow/utils/session.py", line 71, in wrapper
    return func(*args, session=session, **kwargs)
  File "/home/felipe/airflow/venv/lib/python3.9/site-packages/airflow/models/abstractoperator.py", line 344, in _do_render_template_fields
    rendered_content = self.render_template(
  File "/home/felipe/airflow/venv/lib/python3.9/site-packages/airflow/models/abstractoperator.py", line 404, in render_template
    return {key: self.render_template(value, context, jinja_env) for key, value in value.items()}
  File "/home/felipe/airflow/venv/lib/python3.9/site-packages/airflow/models/abstractoperator.py", line 404, in <dictcomp>
    return {key: self.render_template(value, context, jinja_env) for key, value in value.items()}
  File "/home/felipe/airflow/venv/lib/python3.9/site-packages/airflow/models/abstractoperator.py", line 387, in render_template
    template = jinja_env.from_string(value)
  File "/home/felipe/airflow/venv/lib/python3.9/site-packages/jinja2/environment.py", line 1092, in from_string
    return cls.from_code(self, self.compile(source), gs, None)
  File "/home/felipe/airflow/venv/lib/python3.9/site-packages/jinja2/environment.py", line 757, in compile
    self.handle_exception(source=source_hint)
  File "/home/felipe/airflow/venv/lib/python3.9/site-packages/jinja2/environment.py", line 925, in handle_exception
    raise rewrite_traceback_stack(source=source)
  File "<unknown>", line 1, in template
jinja2.exceptions.TemplateSyntaxError: unexpected char '"' at 29
[2023-08-28 20:22:43,263] {taskinstance.py:1395} INFO - Marking task as FAILED. dag_id=dados_climaticos, task_id=extrai_dados, execution_date=20230821T000000, start_date=20230828T232242, end_date=20230828T232243
[2023-08-28 20:22:43,288] {standard_task_runner.py:92} ERROR - Failed to execute job 31 for task extrai_dados (unexpected char '"' at 29; 31162)
[2023-08-28 20:22:43,297] {local_task_job.py:156} INFO - Task exited with return code 1
[2023-08-28 20:22:43,390] {local_task_job.py:273} INFO - 0 downstream tasks scheduled from follow-on schedule check
[2023-08-28 20:31:04,749] {taskinstance.py:1159} INFO - Dependencies all met for <TaskInstance: dados_climaticos.extrai_dados scheduled__2023-08-21T00:00:00+00:00 [queued]>
[2023-08-28 20:31:04,799] {taskinstance.py:1159} INFO - Dependencies all met for <TaskInstance: dados_climaticos.extrai_dados scheduled__2023-08-21T00:00:00+00:00 [queued]>
[2023-08-28 20:31:04,800] {taskinstance.py:1356} INFO - 
--------------------------------------------------------------------------------
[2023-08-28 20:31:04,800] {taskinstance.py:1357} INFO - Starting attempt 1 of 1
[2023-08-28 20:31:04,800] {taskinstance.py:1358} INFO - 
--------------------------------------------------------------------------------
[2023-08-28 20:31:04,908] {taskinstance.py:1377} INFO - Executing <Task(PythonOperator): extrai_dados> on 2023-08-21 00:00:00+00:00
[2023-08-28 20:31:04,972] {standard_task_runner.py:52} INFO - Started process 2492 to run task
[2023-08-28 20:31:04,999] {standard_task_runner.py:79} INFO - Running: ['airflow', 'tasks', 'run', 'dados_climaticos', 'extrai_dados', 'scheduled__2023-08-21T00:00:00+00:00', '--job-id', '31', '--raw', '--subdir', 'DAGS_FOLDER/dados_climaticos.py', '--cfg-path', '/tmp/tmp1ssshvtq', '--error-file', '/tmp/tmpcoggawll']
[2023-08-28 20:31:05,005] {standard_task_runner.py:80} INFO - Job 31: Subtask extrai_dados
[2023-08-28 20:31:05,153] {task_command.py:370} INFO - Running <TaskInstance: dados_climaticos.extrai_dados scheduled__2023-08-21T00:00:00+00:00 [running]> on host FelipeBreve-PC.localdomain
[2023-08-28 20:31:05,234] {taskinstance.py:1889} ERROR - Task failed with exception
Traceback (most recent call last):
  File "/home/felipe/airflow/venv/lib/python3.9/site-packages/airflow/models/taskinstance.py", line 1451, in _run_raw_task
    self._execute_task_with_callbacks(context, test_mode)
  File "/home/felipe/airflow/venv/lib/python3.9/site-packages/airflow/models/taskinstance.py", line 1555, in _execute_task_with_callbacks
    task_orig = self.render_templates(context=context)
  File "/home/felipe/airflow/venv/lib/python3.9/site-packages/airflow/models/taskinstance.py", line 2212, in render_templates
    rendered_task = self.task.render_template_fields(context)
  File "/home/felipe/airflow/venv/lib/python3.9/site-packages/airflow/models/baseoperator.py", line 1185, in render_template_fields
    self._do_render_template_fields(self, self.template_fields, context, jinja_env, set())
  File "/home/felipe/airflow/venv/lib/python3.9/site-packages/airflow/utils/session.py", line 71, in wrapper
    return func(*args, session=session, **kwargs)
  File "/home/felipe/airflow/venv/lib/python3.9/site-packages/airflow/models/abstractoperator.py", line 344, in _do_render_template_fields
    rendered_content = self.render_template(
  File "/home/felipe/airflow/venv/lib/python3.9/site-packages/airflow/models/abstractoperator.py", line 404, in render_template
    return {key: self.render_template(value, context, jinja_env) for key, value in value.items()}
  File "/home/felipe/airflow/venv/lib/python3.9/site-packages/airflow/models/abstractoperator.py", line 404, in <dictcomp>
    return {key: self.render_template(value, context, jinja_env) for key, value in value.items()}
  File "/home/felipe/airflow/venv/lib/python3.9/site-packages/airflow/models/abstractoperator.py", line 387, in render_template
    template = jinja_env.from_string(value)
  File "/home/felipe/airflow/venv/lib/python3.9/site-packages/jinja2/environment.py", line 1092, in from_string
    return cls.from_code(self, self.compile(source), gs, None)
  File "/home/felipe/airflow/venv/lib/python3.9/site-packages/jinja2/environment.py", line 757, in compile
    self.handle_exception(source=source_hint)
  File "/home/felipe/airflow/venv/lib/python3.9/site-packages/jinja2/environment.py", line 925, in handle_exception
    raise rewrite_traceback_stack(source=source)
  File "<unknown>", line 1, in template
jinja2.exceptions.TemplateSyntaxError: unexpected char '"' at 29
[2023-08-28 20:31:05,258] {taskinstance.py:1395} INFO - Marking task as FAILED. dag_id=dados_climaticos, task_id=extrai_dados, execution_date=20230821T000000, start_date=20230828T233104, end_date=20230828T233105
[2023-08-28 20:31:05,288] {standard_task_runner.py:92} ERROR - Failed to execute job 31 for task extrai_dados (unexpected char '"' at 29; 2492)
[2023-08-28 20:31:05,329] {local_task_job.py:156} INFO - Task exited with return code 1
[2023-08-28 20:31:05,481] {local_task_job.py:273} INFO - 0 downstream tasks scheduled from follow-on schedule check
[2023-08-28 20:42:12,920] {taskinstance.py:1159} INFO - Dependencies all met for <TaskInstance: dados_climaticos.extrai_dados scheduled__2023-08-21T00:00:00+00:00 [queued]>
[2023-08-28 20:42:12,961] {taskinstance.py:1159} INFO - Dependencies all met for <TaskInstance: dados_climaticos.extrai_dados scheduled__2023-08-21T00:00:00+00:00 [queued]>
[2023-08-28 20:42:12,961] {taskinstance.py:1356} INFO - 
--------------------------------------------------------------------------------
[2023-08-28 20:42:12,962] {taskinstance.py:1357} INFO - Starting attempt 1 of 1
[2023-08-28 20:42:12,962] {taskinstance.py:1358} INFO - 
--------------------------------------------------------------------------------
[2023-08-28 20:42:13,073] {taskinstance.py:1377} INFO - Executing <Task(PythonOperator): extrai_dados> on 2023-08-21 00:00:00+00:00
[2023-08-28 20:42:13,213] {standard_task_runner.py:52} INFO - Started process 5772 to run task
[2023-08-28 20:42:13,256] {standard_task_runner.py:79} INFO - Running: ['airflow', 'tasks', 'run', 'dados_climaticos', 'extrai_dados', 'scheduled__2023-08-21T00:00:00+00:00', '--job-id', '31', '--raw', '--subdir', 'DAGS_FOLDER/dados_climaticos.py', '--cfg-path', '/tmp/tmpm2_m8_an', '--error-file', '/tmp/tmp18s9ppqo']
[2023-08-28 20:42:13,263] {standard_task_runner.py:80} INFO - Job 31: Subtask extrai_dados
[2023-08-28 20:42:13,696] {task_command.py:370} INFO - Running <TaskInstance: dados_climaticos.extrai_dados scheduled__2023-08-21T00:00:00+00:00 [running]> on host FelipeBreve-PC.localdomain
[2023-08-28 20:42:14,079] {taskinstance.py:1569} INFO - Exporting the following env vars:
AIRFLOW_CTX_DAG_OWNER=airflow
AIRFLOW_CTX_DAG_ID=dados_climaticos
AIRFLOW_CTX_TASK_ID=extrai_dados
AIRFLOW_CTX_EXECUTION_DATE=2023-08-21T00:00:00+00:00
AIRFLOW_CTX_TRY_NUMBER=1
AIRFLOW_CTX_DAG_RUN_ID=scheduled__2023-08-21T00:00:00+00:00
[2023-08-28 20:42:14,951] {python.py:173} INFO - Done. Returned value was: None
[2023-08-28 20:42:14,990] {taskinstance.py:1395} INFO - Marking task as SUCCESS. dag_id=dados_climaticos, task_id=extrai_dados, execution_date=20230821T000000, start_date=20230828T234212, end_date=20230828T234214
[2023-08-28 20:42:15,058] {local_task_job.py:156} INFO - Task exited with return code 0
[2023-08-28 20:42:15,262] {local_task_job.py:273} INFO - 0 downstream tasks scheduled from follow-on schedule check
